## 오류 처리

### ✅ **try / catch**

- try catch 문은 실행할 코드블럭을 표시하고 예외(exception)가 발생(throw)할 경우의 응답을 지정합니다.
- try는 오류 발생 여부를 제어할 수 없는 경우에 사용한다

    ```jsx
    try {
      nonExistentFunction();
    } catch (error) { //이름 지정 보통 error로 칭함
      console.error(error); 
    	// Expected output: ReferenceError: nonExistentFunction is not defined 
    	// (Note: the exact output may be browser-dependent)
    }
    
    ```

- finally는 try 선언이 완료된 이후에 실행된다. 이는 예외 발생 여부와 상관없이 실행된다.

    ```jsx
    try {
      nonExistentFunction();
    } catch (error) { // Typically named "error"
      console.error(error);
      throw error;
    } finally {
      console.error('error');
    }
    
    ```
  
<br>

### ✅ **throw**

- throw문은 사용자 정의 예외를 발생(throw)할 수 있습니다. 예외가 발생하면 현재 함수의 실행이 중지되고 (throw 이후의 명령문은 실행되지 않습니다.), 제어 흐름은 콜스택의 첫 번째 [catch](https://developer.mozilla.org/ko/docs/Web/JavaScript/Reference/Statements/try...catch) 블록으로 전달됩니다. 호출자 함수 사이에 catch 블록이 없으면 프로그램이 종료됩니다.

    ```jsx
    function getRectArea(width, height) {
      if (isNaN(width) || isNaN(height)) {
        throw new Error('Parameter is not a number!');
      }
    }
    
    try {
      getRectArea(3, 'A');
    } catch (e) {
      console.error(e); // Expected output: Error: Parameter is not a number!
    }
    
    ```

- throw는 이런 방식으로도 사용할 수 있다.

    ```jsx
    throw { message: "Invalid user input, not a number!" };`
    ```